[2025-02-11T16:30:45.378+0000] {local_task_job_runner.py:123} INFO - ::group::Pre task execution logs
[2025-02-11T16:30:45.453+0000] {taskinstance.py:2614} INFO - Dependencies all met for dep_context=non-requeueable deps ti=<TaskInstance: kaggle_to_s3_pipeline.upload_to_s3 scheduled__2025-02-10T00:00:00+00:00 [queued]>
[2025-02-11T16:30:45.468+0000] {taskinstance.py:2614} INFO - Dependencies all met for dep_context=requeueable deps ti=<TaskInstance: kaggle_to_s3_pipeline.upload_to_s3 scheduled__2025-02-10T00:00:00+00:00 [queued]>
[2025-02-11T16:30:45.468+0000] {taskinstance.py:2867} INFO - Starting attempt 2 of 2
[2025-02-11T16:30:45.498+0000] {taskinstance.py:2890} INFO - Executing <Task(PythonOperator): upload_to_s3> on 2025-02-10 00:00:00+00:00
[2025-02-11T16:30:45.521+0000] {warnings.py:112} WARNING - /home/***/.local/lib/python3.12/site-packages/***/task/task_runner/standard_task_runner.py:70: DeprecationWarning: This process (pid=192) is multi-threaded, use of fork() may lead to deadlocks in the child.
  pid = os.fork()

[2025-02-11T16:30:45.524+0000] {standard_task_runner.py:72} INFO - Started process 193 to run task
[2025-02-11T16:30:45.524+0000] {standard_task_runner.py:104} INFO - Running: ['***', 'tasks', 'run', 'kaggle_to_s3_pipeline', 'upload_to_s3', 'scheduled__2025-02-10T00:00:00+00:00', '--job-id', '6', '--raw', '--subdir', 'DAGS_FOLDER/s3_data.py', '--cfg-path', '/tmp/tmpk0qlp3kb']
[2025-02-11T16:30:45.529+0000] {standard_task_runner.py:105} INFO - Job 6: Subtask upload_to_s3
[2025-02-11T16:30:45.618+0000] {task_command.py:467} INFO - Running <TaskInstance: kaggle_to_s3_pipeline.upload_to_s3 scheduled__2025-02-10T00:00:00+00:00 [running]> on host a4e66f9d6d3a
[2025-02-11T16:30:45.708+0000] {taskinstance.py:3134} INFO - Exporting env vars: AIRFLOW_CTX_DAG_OWNER='***' AIRFLOW_CTX_DAG_ID='kaggle_to_s3_pipeline' AIRFLOW_CTX_TASK_ID='upload_to_s3' AIRFLOW_CTX_EXECUTION_DATE='2025-02-10T00:00:00+00:00' AIRFLOW_CTX_TRY_NUMBER='2' AIRFLOW_CTX_DAG_RUN_ID='scheduled__2025-02-10T00:00:00+00:00'
[2025-02-11T16:30:45.711+0000] {taskinstance.py:732} INFO - ::endgroup::
[2025-02-11T16:30:47.454+0000] {taskinstance.py:3313} ERROR - Task failed with exception
Traceback (most recent call last):
  File "/home/airflow/.local/lib/python3.12/site-packages/airflow/models/taskinstance.py", line 768, in _execute_task
    result = _execute_callable(context=context, **execute_callable_kwargs)
             ^^^^^^^^^^^^^^^^^^^^^^^^^^^^^^^^^^^^^^^^^^^^^^^^^^^^^^^^^^^^^
  File "/home/airflow/.local/lib/python3.12/site-packages/airflow/models/taskinstance.py", line 734, in _execute_callable
    return ExecutionCallableRunner(
           ^^^^^^^^^^^^^^^^^^^^^^^^
  File "/home/airflow/.local/lib/python3.12/site-packages/airflow/utils/operator_helpers.py", line 252, in run
    return self.func(*args, **kwargs)
           ^^^^^^^^^^^^^^^^^^^^^^^^^^
  File "/home/airflow/.local/lib/python3.12/site-packages/airflow/models/baseoperator.py", line 424, in wrapper
    return func(self, *args, **kwargs)
           ^^^^^^^^^^^^^^^^^^^^^^^^^^^
  File "/home/airflow/.local/lib/python3.12/site-packages/airflow/operators/python.py", line 238, in execute
    return_value = self.execute_callable()
                   ^^^^^^^^^^^^^^^^^^^^^^^
  File "/home/airflow/.local/lib/python3.12/site-packages/airflow/operators/python.py", line 256, in execute_callable
    return runner.run(*self.op_args, **self.op_kwargs)
           ^^^^^^^^^^^^^^^^^^^^^^^^^^^^^^^^^^^^^^^^^^^
  File "/home/airflow/.local/lib/python3.12/site-packages/airflow/utils/operator_helpers.py", line 252, in run
    return self.func(*args, **kwargs)
           ^^^^^^^^^^^^^^^^^^^^^^^^^^
  File "/opt/airflow/dags/s3_data.py", line 26, in upload_to_s3
    s3_client.upload_file(file_path, S3_BUCKET_NAME, S3_KEY)
  File "/home/airflow/.local/lib/python3.12/site-packages/boto3/s3/inject.py", line 145, in upload_file
    return transfer.upload_file(
           ^^^^^^^^^^^^^^^^^^^^^
  File "/home/airflow/.local/lib/python3.12/site-packages/boto3/s3/transfer.py", line 368, in upload_file
    future = self._manager.upload(
             ^^^^^^^^^^^^^^^^^^^^^
  File "/home/airflow/.local/lib/python3.12/site-packages/s3transfer/manager.py", line 337, in upload
    self._validate_if_bucket_supported(bucket)
  File "/home/airflow/.local/lib/python3.12/site-packages/s3transfer/manager.py", line 506, in _validate_if_bucket_supported
    match = pattern.match(bucket)
            ^^^^^^^^^^^^^^^^^^^^^
TypeError: expected string or bytes-like object, got 'NoneType'
[2025-02-11T16:30:47.507+0000] {taskinstance.py:1226} INFO - Marking task as FAILED. dag_id=kaggle_to_s3_pipeline, task_id=upload_to_s3, run_id=scheduled__2025-02-10T00:00:00+00:00, execution_date=20250210T000000, start_date=20250211T163045, end_date=20250211T163047
[2025-02-11T16:30:47.570+0000] {taskinstance.py:341} INFO - ::group::Post task execution logs
[2025-02-11T16:30:47.570+0000] {standard_task_runner.py:124} ERROR - Failed to execute job 6 for task upload_to_s3 (expected string or bytes-like object, got 'NoneType'; 193)
Traceback (most recent call last):
  File "/home/airflow/.local/lib/python3.12/site-packages/airflow/task/task_runner/standard_task_runner.py", line 117, in _start_by_fork
    ret = args.func(args, dag=self.dag)
          ^^^^^^^^^^^^^^^^^^^^^^^^^^^^^
  File "/home/airflow/.local/lib/python3.12/site-packages/airflow/cli/cli_config.py", line 49, in command
    return func(*args, **kwargs)
           ^^^^^^^^^^^^^^^^^^^^^
  File "/home/airflow/.local/lib/python3.12/site-packages/airflow/utils/cli.py", line 116, in wrapper
    return f(*args, **kwargs)
           ^^^^^^^^^^^^^^^^^^
  File "/home/airflow/.local/lib/python3.12/site-packages/airflow/cli/commands/task_command.py", line 483, in task_run
    task_return_code = _run_task_by_selected_method(args, _dag, ti)
                       ^^^^^^^^^^^^^^^^^^^^^^^^^^^^^^^^^^^^^^^^^^^^
  File "/home/airflow/.local/lib/python3.12/site-packages/airflow/cli/commands/task_command.py", line 256, in _run_task_by_selected_method
    return _run_raw_task(args, ti)
           ^^^^^^^^^^^^^^^^^^^^^^^
  File "/home/airflow/.local/lib/python3.12/site-packages/airflow/cli/commands/task_command.py", line 341, in _run_raw_task
    return ti._run_raw_task(
           ^^^^^^^^^^^^^^^^^
  File "/home/airflow/.local/lib/python3.12/site-packages/airflow/utils/session.py", line 97, in wrapper
    return func(*args, session=session, **kwargs)
           ^^^^^^^^^^^^^^^^^^^^^^^^^^^^^^^^^^^^^^
  File "/home/airflow/.local/lib/python3.12/site-packages/airflow/models/taskinstance.py", line 3006, in _run_raw_task
    return _run_raw_task(
           ^^^^^^^^^^^^^^
  File "/home/airflow/.local/lib/python3.12/site-packages/airflow/models/taskinstance.py", line 274, in _run_raw_task
    TaskInstance._execute_task_with_callbacks(
  File "/home/airflow/.local/lib/python3.12/site-packages/airflow/models/taskinstance.py", line 3161, in _execute_task_with_callbacks
    result = self._execute_task(context, task_orig)
             ^^^^^^^^^^^^^^^^^^^^^^^^^^^^^^^^^^^^^^
  File "/home/airflow/.local/lib/python3.12/site-packages/airflow/models/taskinstance.py", line 3185, in _execute_task
    return _execute_task(self, context, task_orig)
           ^^^^^^^^^^^^^^^^^^^^^^^^^^^^^^^^^^^^^^^
  File "/home/airflow/.local/lib/python3.12/site-packages/airflow/models/taskinstance.py", line 768, in _execute_task
    result = _execute_callable(context=context, **execute_callable_kwargs)
             ^^^^^^^^^^^^^^^^^^^^^^^^^^^^^^^^^^^^^^^^^^^^^^^^^^^^^^^^^^^^^
  File "/home/airflow/.local/lib/python3.12/site-packages/airflow/models/taskinstance.py", line 734, in _execute_callable
    return ExecutionCallableRunner(
           ^^^^^^^^^^^^^^^^^^^^^^^^
  File "/home/airflow/.local/lib/python3.12/site-packages/airflow/utils/operator_helpers.py", line 252, in run
    return self.func(*args, **kwargs)
           ^^^^^^^^^^^^^^^^^^^^^^^^^^
  File "/home/airflow/.local/lib/python3.12/site-packages/airflow/models/baseoperator.py", line 424, in wrapper
    return func(self, *args, **kwargs)
           ^^^^^^^^^^^^^^^^^^^^^^^^^^^
  File "/home/airflow/.local/lib/python3.12/site-packages/airflow/operators/python.py", line 238, in execute
    return_value = self.execute_callable()
                   ^^^^^^^^^^^^^^^^^^^^^^^
  File "/home/airflow/.local/lib/python3.12/site-packages/airflow/operators/python.py", line 256, in execute_callable
    return runner.run(*self.op_args, **self.op_kwargs)
           ^^^^^^^^^^^^^^^^^^^^^^^^^^^^^^^^^^^^^^^^^^^
  File "/home/airflow/.local/lib/python3.12/site-packages/airflow/utils/operator_helpers.py", line 252, in run
    return self.func(*args, **kwargs)
           ^^^^^^^^^^^^^^^^^^^^^^^^^^
  File "/opt/airflow/dags/s3_data.py", line 26, in upload_to_s3
    s3_client.upload_file(file_path, S3_BUCKET_NAME, S3_KEY)
  File "/home/airflow/.local/lib/python3.12/site-packages/boto3/s3/inject.py", line 145, in upload_file
    return transfer.upload_file(
           ^^^^^^^^^^^^^^^^^^^^^
  File "/home/airflow/.local/lib/python3.12/site-packages/boto3/s3/transfer.py", line 368, in upload_file
    future = self._manager.upload(
             ^^^^^^^^^^^^^^^^^^^^^
  File "/home/airflow/.local/lib/python3.12/site-packages/s3transfer/manager.py", line 337, in upload
    self._validate_if_bucket_supported(bucket)
  File "/home/airflow/.local/lib/python3.12/site-packages/s3transfer/manager.py", line 506, in _validate_if_bucket_supported
    match = pattern.match(bucket)
            ^^^^^^^^^^^^^^^^^^^^^
TypeError: expected string or bytes-like object, got 'NoneType'
[2025-02-11T16:30:47.646+0000] {local_task_job_runner.py:266} INFO - Task exited with return code 1
[2025-02-11T16:30:47.710+0000] {taskinstance.py:3901} INFO - 0 downstream tasks scheduled from follow-on schedule check
[2025-02-11T16:30:47.711+0000] {local_task_job_runner.py:245} INFO - ::endgroup::
