[2025-02-11T19:02:18.960+0000] {local_task_job_runner.py:123} INFO - ::group::Pre task execution logs
[2025-02-11T19:02:18.991+0000] {taskinstance.py:2614} INFO - Dependencies all met for dep_context=non-requeueable deps ti=<TaskInstance: kaggle_to_s3_pipeline.upload_to_s3 manual__2025-02-11T19:02:06.315842+00:00 [queued]>
[2025-02-11T19:02:19.002+0000] {taskinstance.py:2614} INFO - Dependencies all met for dep_context=requeueable deps ti=<TaskInstance: kaggle_to_s3_pipeline.upload_to_s3 manual__2025-02-11T19:02:06.315842+00:00 [queued]>
[2025-02-11T19:02:19.003+0000] {taskinstance.py:2867} INFO - Starting attempt 1 of 2
[2025-02-11T19:02:19.025+0000] {taskinstance.py:2890} INFO - Executing <Task(PythonOperator): upload_to_s3> on 2025-02-11 19:02:06.315842+00:00
[2025-02-11T19:02:19.069+0000] {warnings.py:112} WARNING - /home/***/.local/lib/python3.12/site-packages/***/task/task_runner/standard_task_runner.py:70: DeprecationWarning: This process (pid=107) is multi-threaded, use of fork() may lead to deadlocks in the child.
  pid = os.fork()

[2025-02-11T19:02:19.072+0000] {standard_task_runner.py:72} INFO - Started process 108 to run task
[2025-02-11T19:02:19.075+0000] {standard_task_runner.py:104} INFO - Running: ['***', 'tasks', 'run', 'kaggle_to_s3_pipeline', 'upload_to_s3', 'manual__2025-02-11T19:02:06.315842+00:00', '--job-id', '46', '--raw', '--subdir', 'DAGS_FOLDER/s3_data.py', '--cfg-path', '/tmp/tmpwg32hb2r']
[2025-02-11T19:02:19.078+0000] {standard_task_runner.py:105} INFO - Job 46: Subtask upload_to_s3
[2025-02-11T19:02:19.161+0000] {task_command.py:467} INFO - Running <TaskInstance: kaggle_to_s3_pipeline.upload_to_s3 manual__2025-02-11T19:02:06.315842+00:00 [running]> on host c0ad99059c95
[2025-02-11T19:02:19.261+0000] {taskinstance.py:3134} INFO - Exporting env vars: AIRFLOW_CTX_DAG_OWNER='***' AIRFLOW_CTX_DAG_ID='kaggle_to_s3_pipeline' AIRFLOW_CTX_TASK_ID='upload_to_s3' AIRFLOW_CTX_EXECUTION_DATE='2025-02-11T19:02:06.315842+00:00' AIRFLOW_CTX_TRY_NUMBER='1' AIRFLOW_CTX_DAG_RUN_ID='manual__2025-02-11T19:02:06.315842+00:00'
[2025-02-11T19:02:19.263+0000] {taskinstance.py:732} INFO - ::endgroup::
[2025-02-11T19:02:19.280+0000] {s3_data.py:46} INFO - Uploading nba.sqlite to S3 bucket capstone*** at nba_data/nba.sqlite
[2025-02-11T19:02:20.138+0000] {s3_data.py:56} ERROR - Error uploading to S3: Failed to upload ./nba_data/nba.sqlite to capstone***/nba_data/nba.sqlite: An error occurred (InvalidAccessKeyId) when calling the PutObject operation: The AWS Access Key Id you provided does not exist in our records.
[2025-02-11T19:02:20.139+0000] {python.py:240} INFO - Done. Returned value was: None
[2025-02-11T19:02:20.159+0000] {taskinstance.py:341} INFO - ::group::Post task execution logs
[2025-02-11T19:02:20.160+0000] {taskinstance.py:353} INFO - Marking task as SUCCESS. dag_id=kaggle_to_s3_pipeline, task_id=upload_to_s3, run_id=manual__2025-02-11T19:02:06.315842+00:00, execution_date=20250211T190206, start_date=20250211T190218, end_date=20250211T190220
[2025-02-11T19:02:20.226+0000] {local_task_job_runner.py:266} INFO - Task exited with return code 0
[2025-02-11T19:02:20.262+0000] {taskinstance.py:3901} INFO - 0 downstream tasks scheduled from follow-on schedule check
[2025-02-11T19:02:20.263+0000] {local_task_job_runner.py:245} INFO - ::endgroup::
